Workbook

Sheet Posts
A1: Post ID | B1: Platform | C1: Date | D1: Content Type | E1: Post Text | F1: Likes | G1: Shares | H1: Comments | I1: Impressions | J1: Reach | K1: Clicks | L1: Hashtags Used | M1: Campaign_Name | N1: Engagement Rate
A2: P001 | B2: Twitter | C2: 45649 | D2: Reel | E2: Check out our latest reel on twitter! | F2: 1461 | G2: 184 | H2: 344 | I2: 21915 | J2: 21675 | K2: 15 | L2: #FutureOfDriving,#AnytimeIsTeslaTime | M2: CybertruckLaunch | N2: =(F2+G2+H2)/I2 -> 0.090759754
A3: P002 | B3: Twitter | C3: 45750 | D3: Text | E3: Check out our latest text on twitter! | F3: 4054 | G3: 389 | H3: 493 | I3: 64864 | J3: 64383 | K3: 117 | L3: #TeslaCoInnovation,#BetterWithTesla | M3: ModelYCampaign | N3: =(F3+G3+H3)/I3 -> 0.076097681
A4: P003 | B4: YouTube | C4: 45789 | D4: Reel | E4: Check out our latest reel on youtube! | F4: 2795 | G4: 105 | H4: 49 | I4: 53105 | J4: 52307 | K4: 204 | L4: #TeslaCoInnovation | M4: FSDUpdate | N4: =(F4+G4+H4)/I4 -> 0.055531494
A5: P004 | B5: Instagram | C5: 45516 | D5: Story | E5: Check out our latest story on instagram! | F5: 2404 | G5: 363 | H5: 138 | I5: 19232 | J5: 18636 | K5: 128 | L5: #EVRevolution | M5: SustainabilityDrive | N5: =(F5+G5+H5)/I5 -> 0.15105033
A6: P005 | B6: YouTube | C6: 45469 | D6: Reel | E6: Check out our latest reel on youtube! | F6: 3557 | G6: 687 | H6: 424 | I6: 71140 | J6: 70701 | K6: 224 | L6: #EVRevolution,#TeslaCoInnovation | M6: CybertruckLaunch | N6: =(F6+G6+H6)/I6 -> 0.065617093
A7: P006 | B7: Facebook | C7: 45596 | D7: Carousel | E7: Check out our latest carousel on facebook! | F7: 2945 | G7: 930 | H7: 355 | I7: 23560 | J7: 23275 | K7: 256 | L7: #TeslaCoInnovation | M7: ModelYCampaign | N7: =(F7+G7+H7)/I7 -> 0.1795416
A8: P007 | B8: Twitter | C8: 45467 | D8: Carousel | E8: Check out our latest carousel on twitter! | F8: 3860 | G8: 201 | H8: 279 | I8: 61760 | J8: 61660 | K8: 235 | L8: #TeslaCoInnovation | M8: ModelYCampaign | N8: =(F8+G8+H8)/I8 -> 0.070272021
A9: P008 | B9: YouTube | C9: 45486 | D9: Image | E9: Check out our latest image on youtube! | F9: 3929 | G9: 262 | H9: 278 | I9: 43219 | J9: 42841 | K9: 39 | L9: #EVRevolution | M9: SustainabilityDrive | N9: =(F9+G9+H9)/I9 -> 0.1034036
A10: P009 | B10: Facebook | C10: 45534 | D10: Text | E10: Check out our latest text on facebook! | F10: 3784 | G10: 808 | H10: 404 | I10: 56760 | J10: 56343 | K10: 131 | L10: #TeslaCoInnovation | M10: ModelYCampaign | N10: =(F10+G10+H10)/I10 -> 0.088019732
A11: P010 | B11: Facebook | C11: 45727 | D11: Image | E11: Check out our latest image on facebook! | F11: 4241 | G11: 902 | H11: 47 | I11: 72097 | J11: 71598 | K11: 167 | L11: #TeslaCoInnovation | M11: ModelYCampaign | N11: =(F11+G11+H11)/I11 -> 0.071986352
A12: P011 | B12: Instagram | C12: 45690 | D12: Story | E12: Check out our latest story on instagram! | F12: 1792 | G12: 614 | H12: 497 | I12: 25088 | J12: 24675 | K12: 65 | L12: #FutureOfDriving | M12: SustainabilityDrive | N12: =(F12+G12+H12)/I12 -> 0.11571269
A13: P012 | B13: Facebook | C13: 45494 | D13: Reel | E13: Check out our latest reel on facebook! | F13: 1946 | G13: 686 | H13: 377 | I13: 23352 | J13: 22982 | K13: 213 | L13: #FutureOfDriving | M13: FSDUpdate | N13: =(F13+G13+H13)/I13 -> 0.12885406
A14: P013 | B14: YouTube | C14: 45614 | D14: Carousel | E14: Check out our latest carousel on youtube! | F14: 1171 | G14: 286 | H14: 231 | I14: 22249 | J14: 21282 | K14: 114 | L14: #EVRevolution | M14: CybertruckLaunch | N14: =(F14+G14+H14)/I14 -> 0.075868578
A15: P014 | B15: Facebook | C15: 45704 | D15: Story | E15: Check out our latest story on facebook! | F15: 4242 | G15: 555 | H15: 131 | I15: 33936 | J15: 33802 | K15: 265 | L15: #FutureOfDriving | N15: =(F15+G15+H15)/I15 -> 0.14521452
A16: P015 | B16: Facebook | C16: 45589 | D16: Video | E16: Check out our latest video on facebook! | F16: 3888 | G16: 604 | H16: 128 | I16: 77760 | J16: 77167 | K16: 20 | L16: #FutureOfDriving | M16: CybertruckLaunch | N16: =(F16+G16+H16)/I16 -> 0.05941358
A17: P016 | B17: Facebook | C17: 45530 | D17: Text | E17: Check out our latest text on facebook! | F17: 3452 | G17: 377 | H17: 360 | I17: 55232 | J17: 55075 | K17: 87 | L17: #FutureOfDriving | M17: FSDUpdate | N17: =(F17+G17+H17)/I17 -> 0.075843714
A18: P017 | B18: Facebook | C18: 45782 | D18: Text | E18: Check out our latest text on facebook! | F18: 4441 | G18: 511 | H18: 70 | I18: 53292 | J18: 53082 | K18: 159 | L18: #EVRevolution | M18: SustainabilityDrive | N18: =(F18+G18+H18)/I18 -> 0.094235533
A19: P018 | B19: Instagram | C19: 45523 | D19: Reel | E19: Check out our latest reel on instagram! | F19: 3000 | G19: 382 | H19: 325 | I19: 36000 | J19: 35819 | K19: 19 | L19: #FutureOfDriving | M19: CybertruckLaunch | N19: =(F19+G19+H19)/I19 -> 0.10297222
A20: P019 | B20: Instagram | C20: 45466 | D20: Video | E20: Check out our latest video on instagram! | F20: 1071 | G20: 519 | H20: 22 | I20: 16065 | J20: 15865 | K20: 103 | L20: #TeslaCoInnovation | M20: SustainabilityDrive | N20: =(F20+G20+H20)/I20 -> 0.10034236
A21: P020 | B21: Instagram | C21: 45544 | D21: Carousel | E21: Check out our latest carousel on instagram! | F21: 4054 | G21: 488 | H21: 373 | I21: 77026 | J21: 76881 | K21: 25 | L21: #TeslaCoInnovation | M21: CybertruckLaunch | N21: =(F21+G21+H21)/I21 -> 0.063809623
A22: P021 | B22: Instagram | C22: 45661 | D22: Reel | E22: Check out our latest reel on instagram! | F22: 4838 | G22: 640 | H22: 128 | I22: 72570 | J22: 72396 | K22: 83 | L22: #FutureOfDriving | M22: SustainabilityDrive | N22: =(F22+G22+H22)/I22 -> 0.077249552
A23: P022 | B23: Facebook | C23: 45715 | D23: Text | E23: Check out our latest text on facebook! | F23: 1570 | G23: 187 | H23: 260 | I23: 25120 | J23: 24613 | K23: 133 | L23: #TeslaCoInnovation | M23: SustainabilityDrive | N23: =(F23+G23+H23)/I23 -> 0.080294586
A24: P023 | B24: Facebook | C24: 45602 | D24: Video | E24: Check out our latest video on facebook! | F24: 1606 | G24: 547 | H24: 316 | I24: 32120 | J24: 31736 | K24: 225 | L24: #TeslaCoInnovation,#AnytimeIsTeslaTime | M24: ModelYCampaign | N24: =(F24+G24+H24)/I24 -> 0.076867995
A25: P024 | B25: Facebook | C25: 45680 | D25: Video | E25: Check out our latest video on facebook! | F25: 3961 | G25: 761 | H25: 131 | I25: 67337 | J25: 66615 | K25: 161 | L25: #FutureOfDriving | M25: FSDUpdate | N25: =(F25+G25+H25)/I25 -> 0.072070333
A26: P025 | B26: Twitter | C26: 45757 | D26: Carousel | E26: Check out our latest carousel on twitter! | F26: 3128 | G26: 211 | H26: 197 | I26: 59432 | J26: 59182 | K26: 238 | L26: #EVRevolution | N26: =(F26+G26+H26)/I26 -> 0.059496568
A27: P026 | B27: YouTube | C27: 45752 | D27: Reel | E27: Check out our latest reel on youtube! | F27: 3009 | G27: 413 | H27: 358 | I27: 42126 | J27: 41309 | K27: 211 | L27: #FutureOfDriving | M27: ModelYCampaign | N27: =(F27+G27+H27)/I27 -> 0.089730808
A28: P027 | B28: YouTube | C28: 45552 | D28: Text | E28: Check out our latest text on youtube! | F28: 2076 | G28: 195 | H28: 104 | I28: 33216 | J28: 32244 | K28: 51 | L28: #FutureOfDriving | M28: SustainabilityDrive | N28: =(F28+G28+H28)/I28 -> 0.071501686
A29: P028 | B29: Instagram | C29: 45720 | D29: Video | E29: Check out our latest video on instagram! | F29: 432 | G29: 624 | H29: 123 | I29: 6912 | J29: 6259 | K29: 79 | L29: #FutureOfDriving | M29: SustainabilityDrive | N29: =(F29+G29+H29)/I29 -> 0.17057292
A30: P029 | B30: Instagram | C30: 45688 | D30: Carousel | E30: Check out our latest carousel on instagram! | F30: 2566 | G30: 118 | H30: 37 | I30: 12830 | J30: 12264 | K30: 221 | L30: #FutureOfDriving | M30: FSDUpdate | N30: =(F30+G30+H30)/I30 -> 0.21208106
A31: P030 | B31: Instagram | C31: 45713 | D31: Video | E31: Check out our latest video on instagram! | F31: 3095 | G31: 39 | H31: 78 | I31: 55710 | J31: 54808 | K31: 93 | L31: #EVRevolution | N31: =(F31+G31+H31)/I31 -> 0.057655717
A32: P031 | B32: Instagram | C32: 45642 | D32: Text | E32: Check out our latest text on instagram! | F32: 438 | G32: 153 | H32: 275 | I32: 3066 | J32: 2701 | K32: 282 | L32: #TeslaCoInnovation | M32: ModelYCampaign | N32: =(F32+G32+H32)/I32 -> 0.28245271
A33: P032 | B33: Twitter | C33: 45504 | D33: Carousel | E33: Check out our latest carousel on twitter! | F33: 2278 | G33: 10 | H33: 321 | I33: 13668 | J33: 12676 | K33: 275 | L33: #EVRevolution | M33: CybertruckLaunch | N33: =(F33+G33+H33)/I33 -> 0.19088382
A34: P033 | B34: Facebook | C34: 45525 | D34: Image | E34: Check out our latest image on facebook! | F34: 1407 | G34: 400 | H34: 351 | I34: 16884 | J34: 15954 | K34: 113 | L34: #TeslaCoInnovation | M34: CybertruckLaunch | N34: =(F34+G34+H34)/I34 -> 0.12781331
A35: P034 | B35: Facebook | C35: 45742 | D35: Text | E35: Check out our latest text on facebook! | F35: 1652 | G35: 89 | H35: 357 | I35: 29736 | J35: 28771 | K35: 215 | L35: #TeslaCoInnovation | M35: FSDUpdate | N35: =(F35+G35+H35)/I35 -> 0.07055421
A36: P035 | B36: Instagram | C36: 45626 | D36: Video | E36: Check out our latest video on instagram! | F36: 3775 | G36: 16 | H36: 239 | I36: 33975 | J36: 33310 | K36: 271 | L36: #FutureOfDriving | M36: ModelYCampaign | N36: =(F36+G36+H36)/I36 -> 0.11861663
A37: P036 | B37: Instagram | C37: 45766 | D37: Story | E37: Check out our latest story on instagram! | F37: 4518 | G37: 285 | H37: 383 | I37: 67770 | J37: 67621 | K37: 31 | L37: #EVRevolution | M37: ModelYCampaign | N37: =(F37+G37+H37)/I37 -> 0.076523535
A38: P037 | B38: Facebook | C38: 45663 | D38: Carousel | E38: Check out our latest carousel on facebook! | F38: 3024 | G38: 925 | H38: 350 | I38: 24192 | J38: 23518 | K38: 36 | L38: #EVRevolution | M38: ModelYCampaign | N38: =(F38+G38+H38)/I38 -> 0.17770337
A39: P038 | B39: YouTube | C39: 45705 | D39: Reel | E39: Check out our latest reel on youtube! | F39: 3138 | G39: 123 | H39: 291 | I39: 28242 | J39: 27550 | K39: 87 | L39: #TeslaCoInnovation | M39: SustainabilityDrive | N39: =(F39+G39+H39)/I39 -> 0.12577013
A40: P039 | B40: Facebook | C40: 45621 | D40: Image | E40: Check out our latest image on facebook! | F40: 3564 | G40: 629 | H40: 177 | I40: 60588 | J40: 59627 | K40: 92 | L40: #TeslaCoInnovation | N40: =(F40+G40+H40)/I40 -> 0.072126494
...

Sheet Campaign Metadata
A1: Campaign_Name | B1: Start_Date | C1: End_Date | D1: Objective | E1: Total_Budget | F1: Target_Platforms | G1: Primary_Hashtags
A2: CybertruckLaunch | B2: 45458 | C2: 45488 | D2: Product Awareness | E2: 150000 | F2: Instagram,Facebook | G2: #EVRevolution,#TeslaCoInnovation
A3: ModelYCampaign | B3: 45566 | C3: 45596 | D3: Customer Engagement | E3: 200000 | F3: Instagram,YouTube | G3: #AnytimeIsTeslaTime,
A4: FSDUpdate | B4: 45651 | C4: 45667 | D4: Vehicle Launch | E4: 250000 | F4: Facebook,Twitter | G4: #SmoothLikeNitroTesla
A5: SustainabilityDrive | B5: 45717 | C5: 45747 | D5: Community Growth | E5: 180000 | F5: Instagram,Twitter | G5: #BetterWithTesla,#FutureOfDriving

Sheet Engagement Summary
A1: Week_Start_Date | B1: Platform | C1: New_Followers | D1: Unfollows | E1: Total_Followers | F1: Engagement_Rate | G1: Ad_Spend
A2: 45446 | B2: Instagram | C2: 1135 | D2: 88 | E2: 344084 | F2: 8.06 | G2: 5904
A3: 45446 | B3: Facebook | C3: 1312 | D3: 310 | E3: 42654 | F3: 4.98 | G3: 9566
A4: 45446 | B4: Twitter | C4: 584 | D4: 169 | E4: 146834 | F4: 8.31 | G4: 26752
A5: 45446 | B5: YouTube | C5: 1535 | D5: 445 | E5: 395536 | F5: 4.11 | G5: 30671
A6: 45453 | B6: Instagram | C6: 656 | D6: 139 | E6: 49157 | F6: 9.05 | G6: 9920
A7: 45453 | B7: Facebook | C7: 1697 | D7: 414 | E7: 316555 | F7: 2.37 | G7: 7924
A8: 45453 | B8: Twitter | C8: 436 | D8: 250 | E8: 254347 | F8: 4.01 | G8: 8912
A9: 45453 | B9: YouTube | C9: 1197 | D9: 203 | E9: 413878 | F9: 3.16 | G9: 21205
A10: 45460 | B10: Instagram | C10: 1048 | D10: 155 | E10: 456946 | F10: 2.46 | G10: 11329
A11: 45460 | B11: Facebook | C11: 1753 | D11: 371 | E11: 169496 | F11: 8.11 | G11: 46670
A12: 45460 | B12: Twitter | C12: 1335 | D12: 40 | E12: 122732 | F12: 8.19 | G12: 22482
A13: 45460 | B13: YouTube | C13: 403 | D13: 66 | E13: 382851 | F13: 3.49 | G13: 24313
... A201: 45789 | B201: YouTube | C201: 119 | D201: 456 | E201: 82558 | F201: 6.81 | G201: 12174

Sheet Task 1A
A1: TASK 1: Cleaned Posts Dataset
A2: Duplicates removed | Dates standardized | Numerics formatted|Each hashtag is split into an individual column
A3: Post ID | B3: Platform | C3: Date | D3: Content Type | E3: Post Text | F3: Likes | G3: Shares | H3: Comments | I3: Impressions | J3: Reach | K3: Clicks | L3: Hashtags Used | O3: Campaign_Name | P3: Reference for Platform Standardization
A4: P001 | B4: Twitter | C4: 45649 | D4: Reel | E4: Check out our latest reel on twitter! | F4: 1461 | G4: 184 | H4: 344 | I4: 21915 | J4: 21675 | K4: 15 | L4: #FutureOfDriving | M4: #AnytimeIsTeslaTime | O4: CybertruckLaunch | Q4: =EXACT(B4,SUBSTITUTE(PROPER(B4),"Youtube","YouTube")) -> TRUE
A5: P002 | B5: Twitter | C5: 45750 | D5: Text | E5: Check out our latest text on twitter! | F5: 4054 | G5: 389 | H5: 493 | I5: 64864 | J5: 64383 | K5: 117 | L5: #TeslaCoInnovation | M5: #BetterWithTesla | O5: ModelYCampaign | Q5: =EXACT(B5,SUBSTITUTE(PROPER(B5),"Youtube","YouTube")) -> TRUE
A6: P003 | B6: YouTube | C6: 45789 | D6: Reel | E6: Check out our latest reel on youtube! | F6: 2795 | G6: 105 | H6: 49 | I6: 53105 | J6: 52307 | K6: 204 | L6: #TeslaCoInnovation | O6: FSDUpdate | Q6: =EXACT(B6,SUBSTITUTE(PROPER(B6),"Youtube","YouTube")) -> TRUE
A7: P004 | B7: Instagram | C7: 45516 | D7: Story | E7: Check out our latest story on instagram! | F7: 2404 | G7: 363 | H7: 138 | I7: 19232 | J7: 18636 | K7: 128 | L7: #EVRevolution | O7: SustainabilityDrive | Q7: =EXACT(B7,SUBSTITUTE(PROPER(B7),"Youtube","YouTube")) -> TRUE
A8: P005 | B8: YouTube | C8: 45469 | D8: Reel | E8: Check out our latest reel on youtube! | F8: 3557 | G8: 687 | H8: 424 | I8: 71140 | J8: 70701 | K8: 224 | L8: #EVRevolution | M8: #TeslaCoInnovation | O8: CybertruckLaunch | Q8: =EXACT(B8,SUBSTITUTE(PROPER(B8),"Youtube","YouTube")) -> TRUE
A9: P006 | B9: Facebook | C9: 45596 | D9: Carousel | E9: Check out our latest carousel on facebook! | F9: 2945 | G9: 930 | H9: 355 | I9: 23560 | J9: 23275 | K9: 256 | L9: #TeslaCoInnovation | O9: ModelYCampaign | Q9: =EXACT(B9,SUBSTITUTE(PROPER(B9),"Youtube","YouTube")) -> TRUE
A10: P007 | B10: Twitter | C10: 45467 | D10: Carousel | E10: Check out our latest carousel on twitter! | F10: 3860 | G10: 201 | H10: 279 | I10: 61760 | J10: 61660 | K10: 235 | L10: #TeslaCoInnovation | O10: ModelYCampaign | Q10: =EXACT(B10,SUBSTITUTE(PROPER(B10),"Youtube","YouTube")) -> TRUE
A11: P008 | B11: YouTube | C11: 45486 | D11: Image | E11: Check out our latest image on youtube! | F11: 3929 | G11: 262 | H11: 278 | I11: 43219 | J11: 42841 | K11: 39 | L11: #EVRevolution | O11: SustainabilityDrive | Q11: =EXACT(B11,SUBSTITUTE(PROPER(B11),"Youtube","YouTube")) -> TRUE
A12: P009 | B12: Facebook | C12: 45534 | D12: Text | E12: Check out our latest text on facebook! | F12: 3784 | G12: 808 | H12: 404 | I12: 56760 | J12: 56343 | K12: 131 | L12: #TeslaCoInnovation | O12: ModelYCampaign | Q12: =EXACT(B12,SUBSTITUTE(PROPER(B12),"Youtube","YouTube")) -> TRUE
A13: P010 | B13: Facebook | C13: 45727 | D13: Image | E13: Check out our latest image on facebook! | F13: 4241 | G13: 902 | H13: 47 | I13: 72097 | J13: 71598 | K13: 167 | L13: #TeslaCoInnovation | O13: ModelYCampaign | Q13: =EXACT(B13,SUBSTITUTE(PROPER(B13),"Youtube","YouTube")) -> TRUE
A14: P011 | B14: Instagram | C14: 45690 | D14: Story | E14: Check out our latest story on instagram! | F14: 1792 | G14: 614 | H14: 497 | I14: 25088 | J14: 24675 | K14: 65 | L14: #FutureOfDriving | O14: SustainabilityDrive | Q14: =EXACT(B14,SUBSTITUTE(PROPER(B14),"Youtube","YouTube")) -> TRUE
A15: P012 | B15: Facebook | C15: 45494 | D15: Reel | E15: Check out our latest reel on facebook! | F15: 1946 | G15: 686 | H15: 377 | I15: 23352 | J15: 22982 | K15: 213 | L15: #FutureOfDriving | O15: FSDUpdate | Q15: =EXACT(B15,SUBSTITUTE(PROPER(B15),"Youtube","YouTube")) -> TRUE
A16: P013 | B16: YouTube | C16: 45614 | D16: Carousel | E16: Check out our latest carousel on youtube! | F16: 1171 | G16: 286 | H16: 231 | I16: 22249 | J16: 21282 | K16: 114 | L16: #EVRevolution | O16: CybertruckLaunch | Q16: =EXACT(B16,SUBSTITUTE(PROPER(B16),"Youtube","YouTube")) -> TRUE
A17: P014 | B17: Facebook | C17: 45704 | D17: Story | E17: Check out our latest story on facebook! | F17: 4242 | G17: 555 | H17: 131 | I17: 33936 | J17: 33802 | K17: 265 | L17: #FutureOfDriving | Q17: =EXACT(B17,SUBSTITUTE(PROPER(B17),"Youtube","YouTube")) -> TRUE
A18: P015 | B18: Facebook | C18: 45589 | D18: Video | E18: Check out our latest video on facebook! | F18: 3888 | G18: 604 | H18: 128 | I18: 77760 | J18: 77167 | K18: 20 | L18: #FutureOfDriving | O18: CybertruckLaunch | Q18: =EXACT(B18,SUBSTITUTE(PROPER(B18),"Youtube","YouTube")) -> TRUE
A19: P016 | B19: Facebook | C19: 45530 | D19: Text | E19: Check out our latest text on facebook! | F19: 3452 | G19: 377 | H19: 360 | I19: 55232 | J19: 55075 | K19: 87 | L19: #FutureOfDriving | O19: FSDUpdate | Q19: =EXACT(B19,SUBSTITUTE(PROPER(B19),"Youtube","YouTube")) -> TRUE
A20: P017 | B20: Facebook | C20: 45782 | D20: Text | E20: Check out our latest text on facebook! | F20: 4441 | G20: 511 | H20: 70 | I20: 53292 | J20: 53082 | K20: 159 | L20: #EVRevolution | O20: SustainabilityDrive | Q20: =EXACT(B20,SUBSTITUTE(PROPER(B20),"Youtube","YouTube")) -> TRUE
A21: P018 | B21: Instagram | C21: 45523 | D21: Reel | E21: Check out our latest reel on instagram! | F21: 3000 | G21: 382 | H21: 325 | I21: 36000 | J21: 35819 | K21: 19 | L21: #FutureOfDriving | O21: CybertruckLaunch | Q21: =EXACT(B21,SUBSTITUTE(PROPER(B21),"Youtube","YouTube")) -> TRUE
A22: P019 | B22: Instagram | C22: 45466 | D22: Video | E22: Check out our latest video on instagram! | F22: 1071 | G22: 519 | H22: 22 | I22: 16065 | J22: 15865 | K22: 103 | L22: #TeslaCoInnovation | O22: SustainabilityDrive | Q22: =EXACT(B22,SUBSTITUTE(PROPER(B22),"Youtube","YouTube")) -> TRUE
A23: P020 | B23: Instagram | C23: 45544 | D23: Carousel | E23: Check out our latest carousel on instagram! | F23: 4054 | G23: 488 | H23: 373 | I23: 77026 | J23: 76881 | K23: 25 | L23: #TeslaCoInnovation | O23: CybertruckLaunch | Q23: =EXACT(B23,SUBSTITUTE(PROPER(B23),"Youtube","YouTube")) -> TRUE
A24: P021 | B24: Instagram | C24: 45661 | D24: Reel | E24: Check out our latest reel on instagram! | F24: 4838 | G24: 640 | H24: 128 | I24: 72570 | J24: 72396 | K24: 83 | L24: #FutureOfDriving | O24: SustainabilityDrive | Q24: =EXACT(B24,SUBSTITUTE(PROPER(B24),"Youtube","YouTube")) -> TRUE
A25: P022 | B25: Facebook | C25: 45715 | D25: Text | E25: Check out our latest text on facebook! | F25: 1570 | G25: 187 | H25: 260 | I25: 25120 | J25: 24613 | K25: 133 | L25: #TeslaCoInnovation | O25: SustainabilityDrive | Q25: =EXACT(B25,SUBSTITUTE(PROPER(B25),"Youtube","YouTube")) -> TRUE
A26: P023 | B26: Facebook | C26: 45602 | D26: Video | E26: Check out our latest video on facebook! | F26: 1606 | G26: 547 | H26: 316 | I26: 32120 | J26: 31736 | K26: 225 | L26: #TeslaCoInnovation | M26: #AnytimeIsTeslaTime | O26: ModelYCampaign | Q26: =EXACT(B26,SUBSTITUTE(PROPER(B26),"Youtube","YouTube")) -> TRUE
A27: P024 | B27: Facebook | C27: 45680 | D27: Video | E27: Check out our latest video on facebook! | F27: 3961 | G27: 761 | H27: 131 | I27: 67337 | J27: 66615 | K27: 161 | L27: #FutureOfDriving | O27: FSDUpdate | Q27: =EXACT(B27,SUBSTITUTE(PROPER(B27),"Youtube","YouTube")) -> TRUE
A28: P025 | B28: Twitter | C28: 45757 | D28: Carousel | E28: Check out our latest carousel on twitter! | F28: 3128 | G28: 211 | H28: 197 | I28: 59432 | J28: 59182 | K28: 238 | L28: #EVRevolution | Q28: =EXACT(B28,SUBSTITUTE(PROPER(B28),"Youtube","YouTube")) -> TRUE
A29: P026 | B29: YouTube | C29: 45752 | D29: Reel | E29: Check out our latest reel on youtube! | F29: 3009 | G29: 413 | H29: 358 | I29: 42126 | J29: 41309 | K29: 211 | L29: #FutureOfDriving | O29: ModelYCampaign | Q29: =EXACT(B29,SUBSTITUTE(PROPER(B29),"Youtube","YouTube")) -> TRUE
A30: P027 | B30: YouTube | C30: 45552 | D30: Text | E30: Check out our latest text on youtube! | F30: 2076 | G30: 195 | H30: 104 | I30: 33216 | J30: 32244 | K30: 51 | L30: #FutureOfDriving | O30: SustainabilityDrive | Q30: =EXACT(B30,SUBSTITUTE(PROPER(B30),"Youtube","YouTube")) -> TRUE
A31: P028 | B31: Instagram | C31: 45720 | D31: Video | E31: Check out our latest video on instagram! | F31: 432 | G31: 624 | H31: 123 | I31: 6912 | J31: 6259 | K31: 79 | L31: #FutureOfDriving | O31: SustainabilityDrive | Q31: =EXACT(B31,SUBSTITUTE(PROPER(B31),"Youtube","YouTube")) -> TRUE
A32: P029 | B32: Instagram | C32: 45688 | D32: Carousel | E32: Check out our latest carousel on instagram! | F32: 2566 | G32: 118 | H32: 37 | I32: 12830 | J32: 12264 | K32: 221 | L32: #FutureOfDriving | O32: FSDUpdate | Q32: =EXACT(B32,SUBSTITUTE(PROPER(B32),"Youtube","YouTube")) -> TRUE
A33: P030 | B33: Instagram | C33: 45713 | D33: Video | E33: Check out our latest video on instagram! | F33: 3095 | G33: 39 | H33: 78 | I33: 55710 | J33: 54808 | K33: 93 | L33: #EVRevolution | Q33: =EXACT(B33,SUBSTITUTE(PROPER(B33),"Youtube","YouTube")) -> TRUE
A34: P031 | B34: Instagram | C34: 45642 | D34: Text | E34: Check out our latest text on instagram! | F34: 438 | G34: 153 | H34: 275 | I34: 3066 | J34: 2701 | K34: 282 | L34: #TeslaCoInnovation | O34: ModelYCampaign | Q34: =EXACT(B34,SUBSTITUTE(PROPER(B34),"Youtube","YouTube")) -> TRUE
A35: P032 | B35: Twitter | C35: 45504 | D35: Carousel | E35: Check out our latest carousel on twitter! | F35: 2278 | G35: 10 | H35: 321 | I35: 13668 | J35: 12676 | K35: 275 | L35: #EVRevolution | O35: CybertruckLaunch | Q35: =EXACT(B35,SUBSTITUTE(PROPER(B35),"Youtube","YouTube")) -> TRUE
A36: P033 | B36: Facebook | C36: 45525 | D36: Image | E36: Check out our latest image on facebook! | F36: 1407 | G36: 400 | H36: 351 | I36: 16884 | J36: 15954 | K36: 113 | L36: #TeslaCoInnovation | O36: CybertruckLaunch | Q36: =EXACT(B36,SUBSTITUTE(PROPER(B36),"Youtube","YouTube")) -> TRUE
A37: P034 | B37: Facebook | C37: 45742 | D37: Text | E37: Check out our latest text on facebook! | F37: 1652 | G37: 89 | H37: 357 | I37: 29736 | J37: 28771 | K37: 215 | L37: #TeslaCoInnovation | O37: FSDUpdate | Q37: =EXACT(B37,SUBSTITUTE(PROPER(B37),"Youtube","YouTube")) -> TRUE
A38: P035 | B38: Instagram | C38: 45626 | D38: Video | E38: Check out our latest video on instagram! | F38: 3775 | G38: 16 | H38: 239 | I38: 33975 | J38: 33310 | K38: 271 | L38: #FutureOfDriving | O38: ModelYCampaign | Q38: =EXACT(B38,SUBSTITUTE(PROPER(B38),"Youtube","YouTube")) -> TRUE
A39: P036 | B39: Instagram | C39: 45766 | D39: Story | E39: Check out our latest story on instagram! | F39: 4518 | G39: 285 | H39: 383 | I39: 67770 | J39: 67621 | K39: 31 | L39: #EVRevolution | O39: ModelYCampaign | Q39: =EXACT(B39,SUBSTITUTE(PROPER(B39),"Youtube","YouTube")) -> TRUE
A40: P037 | B40: Facebook | C40: 45663 | D40: Carousel | E40: Check out our latest carousel on facebook! | F40: 3024 | G40: 925 | H40: 350 | I40: 24192 | J40: 23518 | K40: 36 | L40: #EVRevolution | O40: ModelYCampaign | Q40: =EXACT(B40,SUBSTITUTE(PROPER(B40),"Youtube","YouTube")) -> TRUE
...

Sheet Task 1B
A1: TASK 1: Cleansed Data
A2: Numerics Formatted
A3: Week_Start_Date | B3: Platform | C3: New_Followers | D3: Unfollows | E3: Total_Followers | F3: Engagement_Rate | G3: Ad_Spend
A4: 45446 | B4: Instagram | C4: 1135 | D4: 88 | E4: 344084 | F4: 8.06 | G4: 5904
A5: 45446 | B5: Facebook | C5: 1312 | D5: 310 | E5: 42654 | F5: 4.98 | G5: 9566
A6: 45446 | B6: Twitter | C6: 584 | D6: 169 | E6: 146834 | F6: 8.31 | G6: 26752
A7: 45446 | B7: YouTube | C7: 1535 | D7: 445 | E7: 395536 | F7: 4.11 | G7: 30671
A8: 45453 | B8: Instagram | C8: 656 | D8: 139 | E8: 49157 | F8: 9.05 | G8: 9920
A9: 45453 | B9: Facebook | C9: 1697 | D9: 414 | E9: 316555 | F9: 2.37 | G9: 7924
A10: 45453 | B10: Twitter | C10: 436 | D10: 250 | E10: 254347 | F10: 4.01 | G10: 8912
A11: 45453 | B11: YouTube | C11: 1197 | D11: 203 | E11: 413878 | F11: 3.16 | G11: 21205
A12: 45460 | B12: Instagram | C12: 1048 | D12: 155 | E12: 456946 | F12: 2.46 | G12: 11329
A13: 45460 | B13: Facebook | C13: 1753 | D13: 371 | E13: 169496 | F13: 8.11 | G13: 46670
A14: 45460 | B14: Twitter | C14: 1335 | D14: 40 | E14: 122732 | F14: 8.19 | G14: 22482
A15: 45460 | B15: YouTube | C15: 403 | D15: 66 | E15: 382851 | F15: 3.49 | G15: 24313
... A203: 45789 | B203: YouTube | C203: 119 | D203: 456 | E203: 82558 | F203: 6.81 | G203: 12174

Sheet Hashtag Split in Rows
A1: Post ID | B1: Platform | C1: Date | D1: Content Type | E1: Post Text | F1: Likes | G1: Shares | H1: Comments | I1: Impressions | J1: Reach | K1: Clicks | L1: Hashtags Used | M1: Campaign_Name | N1: Engagement Rate
A2: P001 | B2: Twitter | C2: 45649 | D2: Reel | E2: Check out our latest reel on twitter! | F2: 1461 | G2: 184 | H2: 344 | I2: 21915 | J2: 21675 | K2: 15 | L2: #FutureOfDriving | M2: CybertruckLaunch | N2: =(F2+G2+H2)/I2 -> 0.090759754
A3: P001 | B3: Twitter | C3: 45649 | D3: Reel | E3: Check out our latest reel on twitter! | F3: 1461 | G3: 184 | H3: 344 | I3: 21915 | J3: 21675 | K3: 15 | L3: #AnytimeIsTeslaTime | M3: CybertruckLaunch | N3: =(F3+G3+H3)/I3 -> 0.090759754
A4: P002 | B4: Twitter | C4: 45750 | D4: Text | E4: Check out our latest text on twitter! | F4: 4054 | G4: 389 | H4: 493 | I4: 64864 | J4: 64383 | K4: 117 | L4: #TeslaCoInnovation | M4: ModelYCampaign | N4: =(F4+G4+H4)/I4 -> 0.076097681
A5: P002 | B5: Twitter | C5: 45750 | D5: Text | E5: Check out our latest text on twitter! | F5: 4054 | G5: 389 | H5: 493 | I5: 64864 | J5: 64383 | K5: 117 | L5: #BetterWithTesla | M5: ModelYCampaign | N5: =(F5+G5+H5)/I5 -> 0.076097681
A6: P003 | B6: YouTube | C6: 45789 | D6: Reel | E6: Check out our latest reel on youtube! | F6: 2795 | G6: 105 | H6: 49 | I6: 53105 | J6: 52307 | K6: 204 | L6: #TeslaCoInnovation | M6: FSDUpdate | N6: =(F6+G6+H6)/I6 -> 0.055531494
A7: P004 | B7: Instagram | C7: 45516 | D7: Story | E7: Check out our latest story on instagram! | F7: 2404 | G7: 363 | H7: 138 | I7: 19232 | J7: 18636 | K7: 128 | L7: #EVRevolution | M7: SustainabilityDrive | N7: =(F7+G7+H7)/I7 -> 0.15105033
A8: P005 | B8: YouTube | C8: 45469 | D8: Reel | E8: Check out our latest reel on youtube! | F8: 3557 | G8: 687 | H8: 424 | I8: 71140 | J8: 70701 | K8: 224 | L8: #EVRevolution | M8: CybertruckLaunch | N8: =(F8+G8+H8)/I8 -> 0.065617093
A9: P005 | B9: YouTube | C9: 45469 | D9: Reel | E9: Check out our latest reel on youtube! | F9: 3557 | G9: 687 | H9: 424 | I9: 71140 | J9: 70701 | K9: 224 | L9: #TeslaCoInnovation | M9: CybertruckLaunch | N9: =(F9+G9+H9)/I9 -> 0.065617093
A10: P006 | B10: Facebook | C10: 45596 | D10: Carousel | E10: Check out our latest carousel on facebook! | F10: 2945 | G10: 930 | H10: 355 | I10: 23560 | J10: 23275 | K10: 256 | L10: #TeslaCoInnovation | M10: ModelYCampaign | N10: =(F10+G10+H10)/I10 -> 0.1795416
A11: P007 | B11: Twitter | C11: 45467 | D11: Carousel | E11: Check out our latest carousel on twitter! | F11: 3860 | G11: 201 | H11: 279 | I11: 61760 | J11: 61660 | K11: 235 | L11: #TeslaCoInnovation | M11: ModelYCampaign | N11: =(F11+G11+H11)/I11 -> 0.070272021
A12: P008 | B12: YouTube | C12: 45486 | D12: Image | E12: Check out our latest image on youtube! | F12: 3929 | G12: 262 | H12: 278 | I12: 43219 | J12: 42841 | K12: 39 | L12: #EVRevolution | M12: SustainabilityDrive | N12: =(F12+G12+H12)/I12 -> 0.1034036
A13: P009 | B13: Facebook | C13: 45534 | D13: Text | E13: Check out our latest text on facebook! | F13: 3784 | G13: 808 | H13: 404 | I13: 56760 | J13: 56343 | K13: 131 | L13: #TeslaCoInnovation | M13: ModelYCampaign | N13: =(F13+G13+H13)/I13 -> 0.088019732
... A17: P013 | B17: YouTube | C17: 45614 | D17: Carousel | E17: Check out our latest carousel on youtube! | F17: 1171 | G17: 286 | H17: 231 | I17: 22249 | J17: 21282 | K17: 114 | L17: #EVRevolution | M17: CybertruckLaunch | N17: =(F17+G17+H17)/I17 -> 0.075868578
A18: P014 | B18: Facebook | C18: 45704 | D18: Story | E18: Check out our latest story on facebook! | F18: 4242 | G18: 555 | H18: 131 | I18: 33936 | J18: 33802 | K18: 265 | L18: #FutureOfDriving | N18: =(F18+G18+H18)/I18 -> 0.14521452
A19: P015 | B19: Facebook | C19: 45589 | D19: Video | E19: Check out our latest video on facebook! | F19: 3888 | G19: 604 | H19: 128 | I19: 77760 | J19: 77167 | K19: 20 | L19: #FutureOfDriving | M19: CybertruckLaunch | N19: =(F19+G19+H19)/I19 -> 0.05941358
A20: P016 | B20: Facebook | C20: 45530 | D20: Text | E20: Check out our latest text on facebook! | F20: 3452 | G20: 377 | H20: 360 | I20: 55232 | J20: 55075 | K20: 87 | L20: #FutureOfDriving | M20: FSDUpdate | N20: =(F20+G20+H20)/I20 -> 0.075843714
A21: P017 | B21: Facebook | C21: 45782 | D21: Text | E21: Check out our latest text on facebook! | F21: 4441 | G21: 511 | H21: 70 | I21: 53292 | J21: 53082 | K21: 159 | L21: #EVRevolution | M21: SustainabilityDrive | N21: =(F21+G21+H21)/I21 -> 0.094235533
A22: P018 | B22: Instagram | C22: 45523 | D22: Reel | E22: Check out our latest reel on instagram! | F22: 3000 | G22: 382 | H22: 325 | I22: 36000 | J22: 35819 | K22: 19 | L22: #FutureOfDriving | M22: CybertruckLaunch | N22: =(F22+G22+H22)/I22 -> 0.10297222
A23: P019 | B23: Instagram | C23: 45466 | D23: Video | E23: Check out our latest video on instagram! | F23: 1071 | G23: 519 | H23: 22 | I23: 16065 | J23: 15865 | K23: 103 | L23: #TeslaCoInnovation | M23: SustainabilityDrive | N23: =(F23+G23+H23)/I23 -> 0.10034236
A24: P020 | B24: Instagram | C24: 45544 | D24: Carousel | E24: Check out our latest carousel on instagram! | F24: 4054 | G24: 488 | H24: 373 | I24: 77026 | J24: 76881 | K24: 25 | L24: #TeslaCoInnovation | M24: CybertruckLaunch | N24: =(F24+G24+H24)/I24 -> 0.063809623
A25: P021 | B25: Instagram | C25: 45661 | D25: Reel | E25: Check out our latest reel on instagram! | F25: 4838 | G25: 640 | H25: 128 | I25: 72570 | J25: 72396 | K25: 83 | L25: #FutureOfDriving | M25: SustainabilityDrive | N25: =(F25+G25+H25)/I25 -> 0.077249552
A26: P022 | B26: Facebook | C26: 45715 | D26: Text | E26: Check out our latest text on facebook! | F26: 1570 | G26: 187 | H26: 260 | I26: 25120 | J26: 24613 | K26: 133 | L26: #TeslaCoInnovation | M26: SustainabilityDrive | N26: =(F26+G26+H26)/I26 -> 0.080294586
A27: P023 | B27: Facebook | C27: 45602 | D27: Video | E27: Check out our latest video on facebook! | F27: 1606 | G27: 547 | H27: 316 | I27: 32120 | J27: 31736 | K27: 225 | L27: #TeslaCoInnovation | M27: ModelYCampaign | N27: =(F27+G27+H27)/I27 -> 0.076867995
A28: P023 | B28: Facebook | C28: 45602 | D28: Video | E28: Check out our latest video on facebook! | F28: 1606 | G28: 547 | H28: 316 | I28: 32120 | J28: 31736 | K28: 225 | L28: #AnytimeIsTeslaTime | M28: ModelYCampaign | N28: =(F28+G28+H28)/I28 -> 0.076867995
A29: P024 | B29: Facebook | C29: 45680 | D29: Video | E29: Check out our latest video on facebook! | F29: 3961 | G29: 761 | H29: 131 | I29: 67337 | J29: 66615 | K29: 161 | L29: #FutureOfDriving | M29: FSDUpdate | N29: =(F29+G29+H29)/I29 -> 0.072070333
A30: P025 | B30: Twitter | C30: 45757 | D30: Carousel | E30: Check out our latest carousel on twitter! | F30: 3128 | G30: 211 | H30: 197 | I30: 59432 | J30: 59182 | K30: 238 | L30: #EVRevolution | N30: =(F30+G30+H30)/I30 -> 0.059496568
A31: P026 | B31: YouTube | C31: 45752 | D31: Reel | E31: Check out our latest reel on youtube! | F31: 3009 | G31: 413 | H31: 358 | I31: 42126 | J31: 41309 | K31: 211 | L31: #FutureOfDriving | M31: ModelYCampaign | N31: =(F31+G31+H31)/I31 -> 0.089730808
A32: P027 | B32: YouTube | C32: 45552 | D32: Text | E32: Check out our latest text on youtube! | F32: 2076 | G32: 195 | H32: 104 | I32: 33216 | J32: 32244 | K32: 51 | L32: #FutureOfDriving | M32: SustainabilityDrive | N32: =(F32+G32+H32)/I32 -> 0.071501686
A33: P028 | B33: Instagram | C33: 45720 | D33: Video | E33: Check out our latest video on instagram! | F33: 432 | G33: 624 | H33: 123 | I33: 6912 | J33: 6259 | K33: 79 | L33: #FutureOfDriving | M33: SustainabilityDrive | N33: =(F33+G33+H33)/I33 -> 0.17057292
A34: P029 | B34: Instagram | C34: 45688 | D34: Carousel | E34: Check out our latest carousel on instagram! | F34: 2566 | G34: 118 | H34: 37 | I34: 12830 | J34: 12264 | K34: 221 | L34: #FutureOfDriving | M34: FSDUpdate | N34: =(F34+G34+H34)/I34 -> 0.21208106
A35: P030 | B35: Instagram | C35: 45713 | D35: Video | E35: Check out our latest video on instagram! | F35: 3095 | G35: 39 | H35: 78 | I35: 55710 | J35: 54808 | K35: 93 | L35: #EVRevolution | N35: =(F35+G35+H35)/I35 -> 0.057655717
A36: P031 | B36: Instagram | C36: 45642 | D36: Text | E36: Check out our latest text on instagram! | F36: 438 | G36: 153 | H36: 275 | I36: 3066 | J36: 2701 | K36: 282 | L36: #TeslaCoInnovation | M36: ModelYCampaign | N36: =(F36+G36+H36)/I36 -> 0.28245271
A37: P032 | B37: Twitter | C37: 45504 | D37: Carousel | E37: Check out our latest carousel on twitter! | F37: 2278 | G37: 10 | H37: 321 | I37: 13668 | J37: 12676 | K37: 275 | L37: #EVRevolution | M37: CybertruckLaunch | N37: =(F37+G37+H37)/I37 -> 0.19088382
A38: P033 | B38: Facebook | C38: 45525 | D38: Image | E38: Check out our latest image on facebook! | F38: 1407 | G38: 400 | H38: 351 | I38: 16884 | J38: 15954 | K38: 113 | L38: #TeslaCoInnovation | M38: CybertruckLaunch | N38: =(F38+G38+H38)/I38 -> 0.12781331
A39: P034 | B39: Facebook | C39: 45742 | D39: Text | E39: Check out our latest text on facebook! | F39: 1652 | G39: 89 | H39: 357 | I39: 29736 | J39: 28771 | K39: 215 | L39: #TeslaCoInnovation | M39: FSDUpdate | N39: =(F39+G39+H39)/I39 -> 0.07055421
A40: P035 | B40: Instagram | C40: 45626 | D40: Video | E40: Check out our latest video on instagram! | F40: 3775 | G40: 16 | H40: 239 | I40: 33975 | J40: 33310 | K40: 271 | L40: #FutureOfDriving | M40: ModelYCampaign | N40: =(F40+G40+H40)/I40 -> 0.11861663
A41: P036 | B41: Instagram | C41: 45766 | D41: Story | E41: Check out our latest story on instagram! | F41: 4518 | G41: 285 | H41: 383 | I41: 67770 | J41: 67621 | K41: 31 | L41: #EVRevolution | M41: ModelYCampaign | N41: =(F41+G41+H41)/I41 -> 0.076523535
A42: P037 | B42: Facebook | C42: 45663 | D42: Carousel | E42: Check out our latest carousel on facebook! | F42: 3024 | G42: 925 | H42: 350 | I42: 24192 | J42: 23518 | K42: 36 | L42: #EVRevolution | M42: ModelYCampaign | N42: =(F42+G42+H42)/I42 -> 0.17770337
A43: P038 | B43: YouTube | C43: 45705 | D43: Reel | E43: Check out our latest reel on youtube! | F43: 3138 | G43: 123 | H43: 291 | I43: 28242 | J43: 27550 | K43: 87 | L43: #TeslaCoInnovation | M43: SustainabilityDrive | N43: =(F43+G43+H43)/I43 -> 0.12577013
...

Sheet Task 2A
A1: TASK 2: Engagement Analysis
A2: Average Engagement Rate | Top 10 Posts
A3: Post ID | B3: Platform | C3: Average Engagement Rate | I3: Average Engagement Rate Per Platform
A4: P220 | B4: Instagram | C4: =((Posts!F221+Posts!G221+Posts!H221)/Posts!I221)*100 -> 181.29252 | I4: Twitter | J4: =AVERAGEIF(B4:B303,"Twitter",C4:C303) -> 14.368407
A5: P058 | B5: Instagram | C5: =((Posts!F59+Posts!G59+Posts!H59)/Posts!I59)*100 -> 86.601942 | I5: Instagram | J5: =AVERAGEIF(B4:B303,"Instagram",C4:C303) -> 19.329258
A6: P232 | B6: Twitter | C6: =((Posts!F233+Posts!G233+Posts!H233)/Posts!I233)*100 -> 71.686747 | I6: Facebook | J6: =AVERAGEIF(B4:B303,"Facebook",C4:C303) -> 12.19729
A7: P178 | B7: Instagram | C7: =((Posts!F179+Posts!G179+Posts!H179)/Posts!I179)*100 -> 70.387597 | I7: YouTube | J7: =AVERAGEIF(B4:B303,"YouTube",C4:C303) -> 13.118494
A8: P175 | B8: Instagram | C8: =((Posts!F176+Posts!G176+Posts!H176)/Posts!I176)*100 -> 65.08216
A9: P062 | B9: Twitter | C9: =((Posts!F63+Posts!G63+Posts!H63)/Posts!I63)*100 -> 53.773585
A10: P264 | B10: Twitter | C10: =((Posts!F265+Posts!G265+Posts!H265)/Posts!I265)*100 -> 53.389831
A11: P143 | B11: YouTube | C11: =((Posts!F144+Posts!G144+Posts!H144)/Posts!I144)*100 -> 50.192308
A12: P210 | B12: YouTube | C12: =((Posts!F211+Posts!G211+Posts!H211)/Posts!I211)*100 -> 48.518408
A13: P070 | B13: Facebook | C13: =((Posts!F71+Posts!G71+Posts!H71)/Posts!I71)*100 -> 38.274707
A14: P214 | B14: Instagram | C14: =((Posts!F215+Posts!G215+Posts!H215)/Posts!I215)*100 -> 37.955854
A15: P053 | B15: YouTube | C15: =((Posts!F54+Posts!G54+Posts!H54)/Posts!I54)*100 -> 36.965174
A16: P102 | B16: Twitter | C16: =((Posts!F103+Posts!G103+Posts!H103)/Posts!I103)*100 -> 35.666667
A17: P124 | B17: YouTube | C17: =((Posts!F125+Posts!G125+Posts!H125)/Posts!I125)*100 -> 33.618012
A18: P121 | B18: Instagram | C18: =((Posts!F122+Posts!G122+Posts!H122)/Posts!I122)*100 -> 32.349398
A19: P224 | B19: Facebook | C19: =((Posts!F225+Posts!G225+Posts!H225)/Posts!I225)*100 -> 32.083531
A20: P154 | B20: Instagram | C20: =((Posts!F155+Posts!G155+Posts!H155)/Posts!I155)*100 -> 31.965192
A21: P119 | B21: Instagram | C21: =((Posts!F120+Posts!G120+Posts!H120)/Posts!I120)*100 -> 31.705584
A22: P287 | B22: Instagram | C22: =((Posts!F288+Posts!G288+Posts!H288)/Posts!I288)*100 -> 30.126002
A23: P204 | B23: Instagram | C23: =((Posts!F205+Posts!G205+Posts!H205)/Posts!I205)*100 -> 29.713518
A24: P066 | B24: Twitter | C24: =((Posts!F67+Posts!G67+Posts!H67)/Posts!I67)*100 -> 29.199735
A25: P183 | B25: Instagram | C25: =((Posts!F184+Posts!G184+Posts!H184)/Posts!I184)*100 -> 28.696581
A26: P031 | B26: Instagram | C26: =((Posts!F32+Posts!G32+Posts!H32)/Posts!I32)*100 -> 28.245271
A27: P093 | B27: Instagram | C27: =((Posts!F94+Posts!G94+Posts!H94)/Posts!I94)*100 -> 28.045656
A28: P263 | B28: Instagram | C28: =((Posts!F264+Posts!G264+Posts!H264)/Posts!I264)*100 -> 26.876681
A29: P248 | B29: Facebook | C29: =((Posts!F249+Posts!G249+Posts!H249)/Posts!I249)*100 -> 26.297968
A30: P244 | B30: YouTube | C30: =((Posts!F245+Posts!G245+Posts!H245)/Posts!I245)*100 -> 25.869985
A31: P259 | B31: Facebook | C31: =((Posts!F260+Posts!G260+Posts!H260)/Posts!I260)*100 -> 25.771056
A32: P219 | B32: Twitter | C32: =((Posts!F220+Posts!G220+Posts!H220)/Posts!I220)*100 -> 25.701459
A33: P226 | B33: Instagram | C33: =((Posts!F227+Posts!G227+Posts!H227)/Posts!I227)*100 -> 25.537048
A34: P265 | B34: Twitter | C34: =((Posts!F266+Posts!G266+Posts!H266)/Posts!I266)*100 -> 25.279702
A35: P239 | B35: YouTube | C35: =((Posts!F240+Posts!G240+Posts!H240)/Posts!I240)*100 -> 25.062082
A36: P277 | B36: Facebook | C36: =((Posts!F278+Posts!G278+Posts!H278)/Posts!I278)*100 -> 24.763928
A37: P297 | B37: Twitter | C37: =((Posts!F298+Posts!G298+Posts!H298)/Posts!I298)*100 -> 24.34903
A38: P181 | B38: YouTube | C38: =((Posts!F182+Posts!G182+Posts!H182)/Posts!I182)*100 -> 23.673521
A39: P246 | B39: Facebook | C39: =((Posts!F247+Posts!G247+Posts!H247)/Posts!I247)*100 -> 23.65625
A40: P123 | B40: Instagram | C40: =((Posts!F124+Posts!G124+Posts!H124)/Posts!I124)*100 -> 23.616777
...

Sheet Task 2B
A1: TASK 2: Engagement Analysis
A2: Pivot Tables
B3: Platform | C3: Values
B4: Facebook | E4: Instagram | H4: Twitter | K4: YouTube | N4: Total Sum of Likes | O4: Total Sum of Comments | P4: Total Sum of Shares
A5: Content Type | B5: Sum of Likes | C5: Sum of Comments | D5: Sum of Shares | E5: Sum of Likes | F5: Sum of Comments | G5: Sum of Shares | H5: Sum of Likes | I5: Sum of Comments | J5: Sum of Shares | K5: Sum of Likes | L5: Sum of Comments | M5: Sum of Shares
A6: Carousel | B6: 44476 | C6: 4589 | D6: 7400 | E6: 43948 | F6: 3890 | G6: 6975 | H6: 48649 | I6: 3607 | J6: 5791 | K6: 24926 | L6: 2422 | M6: 6305 | N6: 161999 | O6: 14508 | P6: 26471
A7: Image | B7: 71602 | C7: 6495 | D7: 12904 | E7: 34202 | F7: 2655 | G7: 5286 | H7: 43761 | I7: 5125 | J7: 7110 | K7: 23903 | L7: 2077 | M7: 4310 | N7: 173468 | O7: 16352 | P7: 29610
A8: Reel | B8: 36368 | C8: 3353 | D8: 5964 | E8: 32148 | F8: 3386 | G8: 8110 | H8: 27029 | I8: 1913 | J8: 4550 | K8: 32400 | L8: 2668 | M8: 4577 | N8: 127945 | O8: 11320 | P8: 23201
A9: Story | B9: 29405 | C9: 3223 | D9: 4950 | E9: 42649 | F9: 3846 | G9: 10049 | H9: 20466 | I9: 3026 | J9: 5090 | K9: 31968 | L9: 2012 | M9: 3866 | N9: 124488 | O9: 12107 | P9: 23955
A10: Text | B10: 31963 | C10: 3377 | D10: 4792 | E10: 25567 | F10: 1946 | G10: 5112 | H10: 31899 | I10: 3910 | J10: 4861 | K10: 27067 | L10: 1052 | M10: 3928 | N10: 116496 | O10: 10285 | P10: 18693
A11: Video | B11: 28947 | C11: 2263 | D11: 3171 | E11: 25770 | F11: 2128 | G11: 5912 | H11: 29593 | I11: 3299 | J11: 6326 | K11: 31285 | L11: 2589 | M11: 5586 | N11: 115595 | O11: 10279 | P11: 20995
A12: Grand Total | B12: 242761 | C12: 23300 | D12: 39181 | E12: 204284 | F12: 17851 | G12: 41444 | H12: 201397 | I12: 20880 | J12: 33728 | K12: 171549 | L12: 12820 | M12: 28572 | N12: 819991 | O12: 74851 | P12: 142925
A14: Average Clicks per post by Hashtag
A15: Row Labels | B15: Average of Clicks
A16: #AnytimeIsTeslaTime | B16: 161.2
A17: #BetterWithTesla | B17: 114.85714
A18: #EVRevolution | B18: 151.52941
A19: #FutureOfDriving | B19: 144.03883
A20: #SmoothLikeNitroTesla | B20: 111.8
A21: #TeslaCoInnovation | B21: 158.65421
A22: Grand Total | B22: 150.58702

Sheet Task 2 Data
A1: Post ID | B1: Platform | C1: Date | D1: Content Type | E1: Post Text | F1: Likes | G1: Shares | H1: Comments | I1: Impressions | J1: Reach | K1: Clicks | L1: Hashtags Used | M1: Campaign_Name | N1: Engagement Rate
A2: P001 | B2: Twitter | C2: 45649 | D2: Reel | E2: Check out our latest reel on twitter! | F2: 1461 | G2: 184 | H2: 344 | I2: 21915 | J2: 21675 | K2: 15 | L2: #FutureOfDriving | M2: CybertruckLaunch | N2: =(Table10_1[[#This Row],[Likes]]+Table10_1[[#This Row],[Shares]]+Table10_1[[#This Row],[Comments]])/Table10_1[[#This Row],[Impressions]] -> 0.090759754
A3: P001 | B3: Twitter | C3: 45649 | D3: Reel | E3: Check out our latest reel on twitter! | F3: 1461 | G3: 184 | H3: 344 | I3: 21915 | J3: 21675 | K3: 15 | L3: #AnytimeIsTeslaTime | M3: CybertruckLaunch | N3: =(Table10_1[[#This Row],[Likes]]+Table10_1[[#This Row],[Shares]]+Table10_1[[#This Row],[Comments]])/Table10_1[[#This Row],[Impressions]] -> 0.090759754
A4: P002 | B4: Twitter | C4: 45750 | D4: Text | E4: Check out our latest text on twitter! | F4: 4054 | G4: 389 | H4: 493 | I4: 64864 | J4: 64383 | K4: 117 | L4: #TeslaCoInnovation | M4: ModelYCampaign | N4: =(Table10_1[[#This Row],[Likes]]+Table10_1[[#This Row],[Shares]]+Table10_1[[#This Row],[Comments]])/Table10_1[[#This Row],[Impressions]] -> 0.076097681
A5: P002 | B5: Twitter | C5: 45750 | D5: Text | E5: Check out our latest text on twitter! | F5: 4054 | G5: 389 | H5: 493 | I5: 64864 | J5: 64383 | K5: 117 | L5: #BetterWithTesla | M5: ModelYCampaign | N5: =(Table10_1[[#This Row],[Likes]]+Table10_1[[#This Row],[Shares]]+Table10_1[[#This Row],[Comments]])/Table10_1[[#This Row],[Impressions]] -> 0.076097681
A6: P003 | B6: YouTube | C6: 45789 | D6: Reel | E6: Check out our latest reel on youtube! | F6: 2795 | G6: 105 | H6: 49 | I6: 53105 | J6: 52307 | K6: 204 | L6: #TeslaCoInnovation | M6: FSDUpdate | N6: =(Table10_1[[#This Row],[Likes]]+Table10_1[[#This Row],[Shares]]+Table10_1[[#This Row],[Comments]])/Table10_1[[#This Row],[Impressions]] -> 0.055531494
A7: P004 | B7: Instagram | C7: 45516 | D7: Story | E7: Check out our latest story on instagram! | F7: 2404 | G7: 363 | H7: 138 | I7: 19232 | J7: 18636 | K7: 128 | L7: #EVRevolution | M7: SustainabilityDrive | N7: =(Table10_1[[#This Row],[Likes]]+Table10_1[[#This Row],[Shares]]+Table10_1[[#This Row],[Comments]])/Table10_1[[#This Row],[Impressions]] -> 0.15105033
A8: P005 | B8: YouTube | C8: 45469 | D8: Reel | E8: Check out our latest reel on youtube! | F8: 3557 | G8: 687 | H8: 424 | I8: 71140 | J8: 70701 | K8: 224 | L8: #EVRevolution | M8: CybertruckLaunch | N8: =(Table10_1[[#This Row],[Likes]]+Table10_1[[#This Row],[Shares]]+Table10_1[[#This Row],[Comments]])/Table10_1[[#This Row],[Impressions]] -> 0.065617093
A9: P005 | B9: YouTube | C9: 45469 | D9: Reel | E9: Check out our latest reel on youtube! | F9: 3557 | G9: 687 | H9: 424 | I9: 71140 | J9: 70701 | K9: 224 | L9: #TeslaCoInnovation | M9: CybertruckLaunch | N9: =(Table10_1[[#This Row],[Likes]]+Table10_1[[#This Row],[Shares]]+Table10_1[[#This Row],[Comments]])/Table10_1[[#This Row],[Impressions]] -> 0.065617093
A10: P006 | B10: Facebook | C10: 45596 | D10: Carousel | E10: Check out our latest carousel on facebook! | F10: 2945 | G10: 930 | H10: 355 | I10: 23560 | J10: 23275 | K10: 256 | L10: #TeslaCoInnovation | M10: ModelYCampaign | N10: =(Table10_1[[#This Row],[Likes]]+Table10_1[[#This Row],[Shares]]+Table10_1[[#This Row],[Comments]])/Table10_1[[#This Row],[Impressions]] -> 0.1795416
A11: P007 | B11: Twitter | C11: 45467 | D11: Carousel | E11: Check out our latest carousel on twitter! | F11: 3860 | G11: 201 | H11: 279 | I11: 61760 | J11: 61660 | K11: 235 | L11: #TeslaCoInnovation | M11: ModelYCampaign | N11: =(Table10_1[[#This Row],[Likes]]+Table10_1[[#This Row],[Shares]]+Table10_1[[#This Row],[Comments]])/Table10_1[[#This Row],[Impressions]] -> 0.070272021
A12: P008 | B12: YouTube | C12: 45486 | D12: Image | E12: Check out our latest image on youtube! | F12: 3929 | G12: 262 | H12: 278 | I12: 43219 | J12: 42841 | K12: 39 | L12: #EVRevolution | M12: SustainabilityDrive | N12: =(Table10_1[[#This Row],[Likes]]+Table10_1[[#This Row],[Shares]]+Table10_1[[#This Row],[Comments]])/Table10_1[[#This Row],[Impressions]] -> 0.1034036
A13: P009 | B13: Facebook | C13: 45534 | D13: Text | E13: Check out our latest text on facebook! | F13: 3784 | G13: 808 | H13: 404 | I13: 56760 | J13: 56343 | K13: 131 | L13: #TeslaCoInnovation | M13: ModelYCampaign | N13: =(Table10_1[[#This Row],[Likes]]+Table10_1[[#This Row],[Shares]]+Table10_1[[#This Row],[Comments]])/Table10_1[[#This Row],[Impressions]] -> 0.088019732
... A17: P013 | B17: YouTube | C17: 45614 | D17: Carousel | E17: Check out our latest carousel on youtube! | F17: 1171 | G17: 286 | H17: 231 | I17: 22249 | J17: 21282 | K17: 114 | L17: #EVRevolution | M17: CybertruckLaunch | N17: =(Table10_1[[#This Row],[Likes]]+Table10_1[[#This Row],[Shares]]+Table10_1[[#This Row],[Comments]])/Table10_1[[#This Row],[Impressions]] -> 0.075868578
A18: P014 | B18: Facebook | C18: 45704 | D18: Story | E18: Check out our latest story on facebook! | F18: 4242 | G18: 555 | H18: 131 | I18: 33936 | J18: 33802 | K18: 265 | L18: #FutureOfDriving | N18: =(Table10_1[[#This Row],[Likes]]+Table10_1[[#This Row],[Shares]]+Table10_1[[#This Row],[Comments]])/Table10_1[[#This Row],[Impressions]] -> 0.14521452
A19: P015 | B19: Facebook | C19: 45589 | D19: Video | E19: Check out our latest video on facebook! | F19: 3888 | G19: 604 | H19: 128 | I19: 77760 | J19: 77167 | K19: 20 | L19: #FutureOfDriving | M19: CybertruckLaunch | N19: =(Table10_1[[#This Row],[Likes]]+Table10_1[[#This Row],[Shares]]+Table10_1[[#This Row],[Comments]])/Table10_1[[#This Row],[Impressions]] -> 0.05941358
A20: P016 | B20: Facebook | C20: 45530 | D20: Text | E20: Check out our latest text on facebook! | F20: 3452 | G20: 377 | H20: 360 | I20: 55232 | J20: 55075 | K20: 87 | L20: #FutureOfDriving | M20: FSDUpdate | N20: =(Table10_1[[#This Row],[Likes]]+Table10_1[[#This Row],[Shares]]+Table10_1[[#This Row],[Comments]])/Table10_1[[#This Row],[Impressions]] -> 0.075843714
A21: P017 | B21: Facebook | C21: 45782 | D21: Text | E21: Check out our latest text on facebook! | F21: 4441 | G21: 511 | H21: 70 | I21: 53292 | J21: 53082 | K21: 159 | L21: #EVRevolution | M21: SustainabilityDrive | N21: =(Table10_1[[#This Row],[Likes]]+Table10_1[[#This Row],[Shares]]+Table10_1[[#This Row],[Comments]])/Table10_1[[#This Row],[Impressions]] -> 0.094235533
A22: P018 | B22: Instagram | C22: 45523 | D22: Reel | E22: Check out our latest reel on instagram! | F22: 3000 | G22: 382 | H22: 325 | I22: 36000 | J22: 35819 | K22: 19 | L22: #FutureOfDriving | M22: CybertruckLaunch | N22: =(Table10_1[[#This Row],[Likes]]+Table10_1[[#This Row],[Shares]]+Table10_1[[#This Row],[Comments]])/Table10_1[[#This Row],[Impressions]] -> 0.10297222
A23: P019 | B23: Instagram | C23: 45466 | D23: Video | E23: Check out our latest video on instagram! | F23: 1071 | G23: 519 | H23: 22 | I23: 16065 | J23: 15865 | K23: 103 | L23: #TeslaCoInnovation | M23: SustainabilityDrive | N23: =(Table10_1[[#This Row],[Likes]]+Table10_1[[#This Row],[Shares]]+Table10_1[[#This Row],[Comments]])/Table10_1[[#This Row],[Impressions]] -> 0.10034236
A24: P020 | B24: Instagram | C24: 45544 | D24: Carousel | E24: Check out our latest carousel on instagram! | F24: 4054 | G24: 488 | H24: 373 | I24: 77026 | J24: 76881 | K24: 25 | L24: #TeslaCoInnovation | M24: CybertruckLaunch | N24: =(Table10_1[[#This Row],[Likes]]+Table10_1[[#This Row],[Shares]]+Table10_1[[#This Row],[Comments]])/Table10_1[[#This Row],[Impressions]] -> 0.063809623
A25: P021 | B25: Instagram | C25: 45661 | D25: Reel | E25: Check out our latest reel on instagram! | F25: 4838 | G25: 640 | H25: 128 | I25: 72570 | J25: 72396 | K25: 83 | L25: #FutureOfDriving | M25: SustainabilityDrive | N25: =(Table10_1[[#This Row],[Likes]]+Table10_1[[#This Row],[Shares]]+Table10_1[[#This Row],[Comments]])/Table10_1[[#This Row],[Impressions]] -> 0.077249552
A26: P022 | B26: Facebook | C26: 45715 | D26: Text | E26: Check out our latest text on facebook! | F26: 1570 | G26: 187 | H26: 260 | I26: 25120 | J26: 24613 | K26: 133 | L26: #TeslaCoInnovation | M26: SustainabilityDrive | N26: =(Table10_1[[#This Row],[Likes]]+Table10_1[[#This Row],[Shares]]+Table10_1[[#This Row],[Comments]])/Table10_1[[#This Row],[Impressions]] -> 0.080294586
A27: P023 | B27: Facebook | C27: 45602 | D27: Video | E27: Check out our latest video on facebook! | F27: 1606 | G27: 547 | H27: 316 | I27: 32120 | J27: 31736 | K27: 225 | L27: #TeslaCoInnovation | M27: ModelYCampaign | N27: =(Table10_1[[#This Row],[Likes]]+Table10_1[[#This Row],[Shares]]+Table10_1[[#This Row],[Comments]])/Table10_1[[#This Row],[Impressions]] -> 0.076867995
A28: P023 | B28: Facebook | C28: 45602 | D28: Video | E28: Check out our latest video on facebook! | F28: 1606 | G28: 547 | H28: 316 | I28: 32120 | J28: 31736 | K28: 225 | L28: #AnytimeIsTeslaTime | M28: ModelYCampaign | N28: =(Table10_1[[#This Row],[Likes]]+Table10_1[[#This Row],[Shares]]+Table10_1[[#This Row],[Comments]])/Table10_1[[#This Row],[Impressions]] -> 0.076867995
A29: P024 | B29: Facebook | C29: 45680 | D29: Video | E29: Check out our latest video on facebook! | F29: 3961 | G29: 761 | H29: 131 | I29: 67337 | J29: 66615 | K29: 161 | L29: #FutureOfDriving | M29: FSDUpdate | N29: =(Table10_1[[#This Row],[Likes]]+Table10_1[[#This Row],[Shares]]+Table10_1[[#This Row],[Comments]])/Table10_1[[#This Row],[Impressions]] -> 0.072070333
A30: P025 | B30: Twitter | C30: 45757 | D30: Carousel | E30: Check out our latest carousel on twitter! | F30: 3128 | G30: 211 | H30: 197 | I30: 59432 | J30: 59182 | K30: 238 | L30: #EVRevolution | N30: =(Table10_1[[#This Row],[Likes]]+Table10_1[[#This Row],[Shares]]+Table10_1[[#This Row],[Comments]])/Table10_1[[#This Row],[Impressions]] -> 0.059496568
A31: P026 | B31: YouTube | C31: 45752 | D31: Reel | E31: Check out our latest reel on youtube! | F31: 3009 | G31: 413 | H31: 358 | I31: 42126 | J31: 41309 | K31: 211 | L31: #FutureOfDriving | M31: ModelYCampaign | N31: =(Table10_1[[#This Row],[Likes]]+Table10_1[[#This Row],[Shares]]+Table10_1[[#This Row],[Comments]])/Table10_1[[#This Row],[Impressions]] -> 0.089730808
A32: P027 | B32: YouTube | C32: 45552 | D32: Text | E32: Check out our latest text on youtube! | F32: 2076 | G32: 195 | H32: 104 | I32: 33216 | J32: 32244 | K32: 51 | L32: #FutureOfDriving | M32: SustainabilityDrive | N32: =(Table10_1[[#This Row],[Likes]]+Table10_1[[#This Row],[Shares]]+Table10_1[[#This Row],[Comments]])/Table10_1[[#This Row],[Impressions]] -> 0.071501686
A33: P028 | B33: Instagram | C33: 45720 | D33: Video | E33: Check out our latest video on instagram! | F33: 432 | G33: 624 | H33: 123 | I33: 6912 | J33: 6259 | K33: 79 | L33: #FutureOfDriving | M33: SustainabilityDrive | N33: =(Table10_1[[#This Row],[Likes]]+Table10_1[[#This Row],[Shares]]+Table10_1[[#This Row],[Comments]])/Table10_1[[#This Row],[Impressions]] -> 0.17057292
A34: P029 | B34: Instagram | C34: 45688 | D34: Carousel | E34: Check out our latest carousel on instagram! | F34: 2566 | G34: 118 | H34: 37 | I34: 12830 | J34: 12264 | K34: 221 | L34: #FutureOfDriving | M34: FSDUpdate | N34: =(Table10_1[[#This Row],[Likes]]+Table10_1[[#This Row],[Shares]]+Table10_1[[#This Row],[Comments]])/Table10_1[[#This Row],[Impressions]] -> 0.21208106
A35: P030 | B35: Instagram | C35: 45713 | D35: Video | E35: Check out our latest video on instagram! | F35: 3095 | G35: 39 | H35: 78 | I35: 55710 | J35: 54808 | K35: 93 | L35: #EVRevolution | N35: =(Table10_1[[#This Row],[Likes]]+Table10_1[[#This Row],[Shares]]+Table10_1[[#This Row],[Comments]])/Table10_1[[#This Row],[Impressions]] -> 0.057655717
A36: P031 | B36: Instagram | C36: 45642 | D36: Text | E36: Check out our latest text on instagram! | F36: 438 | G36: 153 | H36: 275 | I36: 3066 | J36: 2701 | K36: 282 | L36: #TeslaCoInnovation | M36: ModelYCampaign | N36: =(Table10_1[[#This Row],[Likes]]+Table10_1[[#This Row],[Shares]]+Table10_1[[#This Row],[Comments]])/Table10_1[[#This Row],[Impressions]] -> 0.28245271
A37: P032 | B37: Twitter | C37: 45504 | D37: Carousel | E37: Check out our latest carousel on twitter! | F37: 2278 | G37: 10 | H37: 321 | I37: 13668 | J37: 12676 | K37: 275 | L37: #EVRevolution | M37: CybertruckLaunch | N37: =(Table10_1[[#This Row],[Likes]]+Table10_1[[#This Row],[Shares]]+Table10_1[[#This Row],[Comments]])/Table10_1[[#This Row],[Impressions]] -> 0.19088382
A38: P033 | B38: Facebook | C38: 45525 | D38: Image | E38: Check out our latest image on facebook! | F38: 1407 | G38: 400 | H38: 351 | I38: 16884 | J38: 15954 | K38: 113 | L38: #TeslaCoInnovation | M38: CybertruckLaunch | N38: =(Table10_1[[#This Row],[Likes]]+Table10_1[[#This Row],[Shares]]+Table10_1[[#This Row],[Comments]])/Table10_1[[#This Row],[Impressions]] -> 0.12781331
A39: P034 | B39: Facebook | C39: 45742 | D39: Text | E39: Check out our latest text on facebook! | F39: 1652 | G39: 89 | H39: 357 | I39: 29736 | J39: 28771 | K39: 215 | L39: #TeslaCoInnovation | M39: FSDUpdate | N39: =(Table10_1[[#This Row],[Likes]]+Table10_1[[#This Row],[Shares]]+Table10_1[[#This Row],[Comments]])/Table10_1[[#This Row],[Impressions]] -> 0.07055421
A40: P035 | B40: Instagram | C40: 45626 | D40: Video | E40: Check out our latest video on instagram! | F40: 3775 | G40: 16 | H40: 239 | I40: 33975 | J40: 33310 | K40: 271 | L40: #FutureOfDriving | M40: ModelYCampaign | N40: =(Table10_1[[#This Row],[Likes]]+Table10_1[[#This Row],[Shares]]+Table10_1[[#This Row],[Comments]])/Table10_1[[#This Row],[Impressions]] -> 0.11861663
A41: P036 | B41: Instagram | C41: 45766 | D41: Story | E41: Check out our latest story on instagram! | F41: 4518 | G41: 285 | H41: 383 | I41: 67770 | J41: 67621 | K41: 31 | L41: #EVRevolution | M41: ModelYCampaign | N41: =(Table10_1[[#This Row],[Likes]]+Table10_1[[#This Row],[Shares]]+Table10_1[[#This Row],[Comments]])/Table10_1[[#This Row],[Impressions]] -> 0.076523535
A42: P037 | B42: Facebook | C42: 45663 | D42: Carousel | E42: Check out our latest carousel on facebook! | F42: 3024 | G42: 925 | H42: 350 | I42: 24192 | J42: 23518 | K42: 36 | L42: #EVRevolution | M42: ModelYCampaign | N42: =(Table10_1[[#This Row],[Likes]]+Table10_1[[#This Row],[Shares]]+Table10_1[[#This Row],[Comments]])/Table10_1[[#This Row],[Impressions]] -> 0.17770337
A43: P038 | B43: YouTube | C43: 45705 | D43: Reel | E43: Check out our latest reel on youtube! | F43: 3138 | G43: 123 | H43: 291 | I43: 28242 | J43: 27550 | K43: 87 | L43: #TeslaCoInnovation | M43: SustainabilityDrive | N43: =(Table10_1[[#This Row],[Likes]]+Table10_1[[#This Row],[Shares]]+Table10_1[[#This Row],[Comments]])/Table10_1[[#This Row],[Impressions]] -> 0.12577013
...

Sheet Task 3
A1: Post ID | B1: Platform | C1: Likes | D1: Shares | E1: Comments | F1: Impressions | G1: Average Engagement Rate | J1: TASK 3: Platform Analysis
A2: P001 | B2: Twitter | C2: 1461 | D2: 184 | E2: 344 | F2: 21915 | G2: =((Posts!F2+Posts!G2+Posts!H2)/Posts!I2)*100 -> 9.0759754 | J2: Engagement | Follower Growth | Ad Spend ROI | Strategy Recommendation
A3: P002 | B3: Twitter | C3: 4054 | D3: 389 | E3: 493 | F3: 64864 | G3: =((Posts!F3+Posts!G3+Posts!H3)/Posts!I3)*100 -> 7.6097681
A4: P003 | B4: YouTube | C4: 2795 | D4: 105 | E4: 49 | F4: 53105 | G4: =((Posts!F4+Posts!G4+Posts!H4)/Posts!I4)*100 -> 5.5531494 | J4: Highlighted Platform with Highest Engagement
A5: P004 | B5: Instagram | C5: 2404 | D5: 363 | E5: 138 | F5: 19232 | G5: =((Posts!F5+Posts!G5+Posts!H5)/Posts!I5)*100 -> 15.105033 | J5: Row Labels | K5: Sum of Likes | L5: Sum of Shares | M5: Sum of Comments | N5: Sum of Impressions | O5: Average of Average Engagement Rate
A6: P005 | B6: YouTube | C6: 3557 | D6: 687 | E6: 424 | F6: 71140 | G6: =((Posts!F6+Posts!G6+Posts!H6)/Posts!I6)*100 -> 6.5617093 | J6: Facebook | K6: 242761 | L6: 39181 | M6: 23300 | N6: 3239154 | O6: 12.19729
A7: P006 | B7: Facebook | C7: 2945 | D7: 930 | E7: 355 | F7: 23560 | G7: =((Posts!F7+Posts!G7+Posts!H7)/Posts!I7)*100 -> 17.95416 | J7: Instagram | K7: 204284 | L7: 41444 | M7: 17851 | N7: 2325756 | O7: 19.329258
A8: P007 | B8: Twitter | C8: 3860 | D8: 201 | E8: 279 | F8: 61760 | G8: =((Posts!F8+Posts!G8+Posts!H8)/Posts!I8)*100 -> 7.0272021 | J8: Twitter | K8: 201397 | L8: 33728 | M8: 20880 | N8: 2560836 | O8: 14.368407
A9: P008 | B9: YouTube | C9: 3929 | D9: 262 | E9: 278 | F9: 43219 | G9: =((Posts!F9+Posts!G9+Posts!H9)/Posts!I9)*100 -> 10.34036 | J9: YouTube | K9: 171549 | L9: 28572 | M9: 12820 | N9: 2268407 | O9: 13.118494
A10: P009 | B10: Facebook | C10: 3784 | D10: 808 | E10: 404 | F10: 56760 | G10: =((Posts!F10+Posts!G10+Posts!H10)/Posts!I10)*100 -> 8.8019732 | J10: Grand Total | K10: 819991 | L10: 142925 | M10: 74851 | N10: 10394153 | O10: 14.828272
A11: P010 | B11: Facebook | C11: 4241 | D11: 902 | E11: 47 | F11: 72097 | G11: =((Posts!F11+Posts!G11+Posts!H11)/Posts!I11)*100 -> 7.1986352 | J11: Follower Growth rates across Platforms
A12: P011 | B12: Instagram | C12: 1792 | D12: 614 | E12: 497 | F12: 25088 | G12: =((Posts!F12+Posts!G12+Posts!H12)/Posts!I12)*100 -> 11.571269 | J12: Platform | K12: Total New Follows | L12: Total Unfollows | M12: Net Growth | N12: Growth Rate
A13: P012 | B13: Facebook | C13: 1946 | D13: 686 | E13: 377 | F13: 23352 | G13: =((Posts!F13+Posts!G13+Posts!H13)/Posts!I13)*100 -> 12.885406 | J13: Facebook | K13: =SUMIF('Task 3'!B2:B201,"Facebook",'Engagement Summary'!C2:C201) -> 51171 | L13: =SUMIF('Engagement Summary'!B2:B201,'Task 3'!J13,'Engagement Summary'!D2:D201) -> 15305 | M13: =K13-L13 -> 35866 | N13: =('Engagement Summary'!C2-'Engagement Summary'!D2)/'Engagement Summary'!E2 -> 0.0030428616
A14: P013 | B14: YouTube | C14: 1171 | D14: 286 | E14: 231 | F14: 22249 | G14: =((Posts!F14+Posts!G14+Posts!H14)/Posts!I14)*100 -> 7.5868578 | J14: Instagram | K14: =SUMIF('Task 3'!B3:B202,'Task 3'!J14,'Engagement Summary'!C3:C202) -> 61771 | L14: =SUMIF('Engagement Summary'!B3:B202,'Task 3'!J14,'Engagement Summary'!D3:D202) -> 10219 | M14: =K14-L14 -> 51552 | N14: =('Engagement Summary'!C3-'Engagement Summary'!D3)/'Engagement Summary'!E3 -> 0.023491349
A15: P014 | B15: Facebook | C15: 4242 | D15: 555 | E15: 131 | F15: 33936 | G15: =((Posts!F15+Posts!G15+Posts!H15)/Posts!I15)*100 -> 14.521452 | J15: YouTube | K15: =SUMIF('Task 3'!B4:B203,'Task 3'!J15,'Engagement Summary'!C4:C203) -> 42900 | L15: =SUMIF('Engagement Summary'!B4:B203,'Task 3'!J15,'Engagement Summary'!D4:D203) -> 12104 | M15: =K15-L15 -> 30796 | N15: =('Engagement Summary'!C4-'Engagement Summary'!D4)/'Engagement Summary'!E4 -> 0.0028263209
A16: P015 | B16: Facebook | C16: 3888 | D16: 604 | E16: 128 | F16: 77760 | G16: =((Posts!F16+Posts!G16+Posts!H16)/Posts!I16)*100 -> 5.941358 | J16: Twitter | K16: =SUMIF('Task 3'!B5:B204,'Task 3'!J16,'Engagement Summary'!C5:C204) -> 51839 | L16: =SUMIF('Engagement Summary'!B5:B204,'Task 3'!J16,'Engagement Summary'!D5:D204) -> 12138 | M16: =K16-L16 -> 39701 | N16: =('Engagement Summary'!C5-'Engagement Summary'!D5)/'Engagement Summary'!E5 -> 0.0027557542
A17: P016 | B17: Facebook | C17: 3452 | D17: 377 | E17: 360 | F17: 55232 | G17: =((Posts!F17+Posts!G17+Posts!H17)/Posts!I17)*100 -> 7.5843714
